Workbook

Sheet moras
A1: IDENTIFICACION | B1: SEXO | C1: SALARIO | D1: TIPO_ASEGURAMIENTO | E1: SECTOR | F1: INDICADOR_ACTIVO | G1: INDICADOR.EXTRANJERO | H1: INDICADOR_MOROSO | I1: EDAD
A2: 1 | B2: HOMBRE | D2: ASALARIADO | E2: SECTOR PUBLICO | F2: SI | G2: NO | H2: NO | I2: 42
A3: 2 | B3: HOMBRE | C3: 3315014 | D3: PENSIONADOS EN SU PROPIO SISTEMA | E3: SECTOR PUBLICO | F3: SI | G3: NO | H3: NO | I3: 77
A4: 3 | B4: MUJER | C4: 270486.01 | D4: ASALARIADO | E4: SECTOR PRIVADO | F4: SI | G4: NO | H4: NO | I4: 45
A5: 4 | B5: MUJER | C5: 544949.83 | D5: ASALARIADO | E5: SECTOR PRIVADO | F5: SI | G5: NO | H5: NO | I5: 49
A6: 5 | B6: MUJER | C6: 210000 | D6: ASALARIADO | E6: SECTOR PRIVADO | F6: SI | G6: NO | H6: NO | I6: 42
A7: 6 | B7: HOMBRE | C7: 397150 | D7: ASALARIADO | E7: SECTOR PRIVADO | F7: SI | G7: NO | H7: NO | I7: 44
A8: 7 | B8: HOMBRE | C8: 854712 | D8: ASALARIADO | E8: SECTOR PRIVADO | F8: SI | G8: NO | H8: NO | I8: 38
A9: 8 | B9: HOMBRE | C9: 401000 | D9: ASALARIADO | E9: SECTOR PRIVADO | F9: SI | G9: SI | H9: SI | I9: 36
A10: 9 | B10: MUJER | C10: 264703.96 | D10: ASALARIADO | E10: SECTOR PRIVADO | F10: SI | G10: NO | H10: NO | I10: 21
A11: 10 | B11: HOMBRE | C11: 4677126.8 | D11: ASALARIADO | E11: SECTOR PRIVADO | F11: SI | G11: NO | H11: NO | I11: 40
A12: 11 | B12: MUJER | C12: 1200000 | D12: ASALARIADO | E12: SECTOR PRIVADO | F12: SI | G12: NO | H12: NO | I12: 30
A13: 12 | B13: MUJER | C13: 1030132 | D13: ASALARIADO | E13: SECTOR PUBLICO | F13: SI | G13: NO | H13: SI | I13: 58
A14: 13 | B14: HOMBRE | C14: 731287.5 | D14: ASALARIADO | E14: SECTOR PUBLICO | F14: SI | G14: NO | H14: NO | I14: 40
... A21: 20 | B21: MUJER | C21: 309820 | D21: ASEGURADO VOLUNTARIO | E21: SECTOR PRIVADO | F21: SI | G21: SI | H21: SI | I21: 52
A22: 21 | B22: MUJER | D22: ASALARIADO | E22: SECTOR PRIVADO | F22: SI | G22: SI | H22: NO | I22: 28
A23: 22 | B23: HOMBRE | C23: 278030 | D23: CONVENIOS ESPECIALES DE TRABAJADORES INDEPENDIENTES | E23: SECTOR PRIVADO | F23: SI | G23: NO | H23: NO | I23: 59
A24: 23 | B24: HOMBRE | C24: 2124814 | D24: ASALARIADO | E24: SECTOR PRIVADO | F24: SI | G24: NO | H24: NO | I24: 32
A25: 24 | B25: HOMBRE | C25: 191744.68 | D25: ASALARIADO | E25: SECTOR PRIVADO | F25: SI | G25: NO | H25: NO | I25: 18
A26: 25 | B26: MUJER | C26: 1117489 | D26: ASALARIADO | E26: SECTOR PUBLICO | F26: SI | G26: NO | H26: SI | I26: 36
A27: 26 | B27: HOMBRE | C27: 1451530 | D27: PENSIONADOS EN SU PROPIO SISTEMA | E27: SECTOR PUBLICO | F27: SI | G27: NO | H27: NO | I27: 62
A28: 27 | B28: HOMBRE | C28: 66700 | D28: ASALARIADO | E28: SECTOR PRIVADO | F28: SI | G28: NO | H28: NO | I28: 38
A29: 28 | B29: MUJER | C29: 73410 | D29: ASALARIADO | E29: SECTOR PRIVADO | F29: SI | G29: SI | H29: NO | I29: 22
A30: 29 | B30: HOMBRE | C30: 815355.66 | D30: ASALARIADO | E30: SECTOR PUBLICO | F30: SI | G30: NO | H30: NO | I30: 42
A31: 30 | B31: HOMBRE | C31: 398125 | D31: ASALARIADO | E31: SECTOR PRIVADO | F31: SI | G31: NO | H31: NO | I31: 38
A32: 31 | B32: HOMBRE | C32: 606763.96 | D32: ASALARIADO | E32: SECTOR PRIVADO | F32: SI | G32: NO | H32: NO | I32: 39
A33: 32 | B33: HOMBRE | C33: 360420 | D33: TRABAJADOR INDEPENDIENTE | E33: SECTOR PRIVADO | F33: SI | G33: NO | H33: SI | I33: 53
A34: 33 | B34: MUJER | C34: 297046 | D34: ASALARIADO | E34: SECTOR PRIVADO | F34: SI | G34: SI | H34: NO | I34: 41
... A36: 35 | B36: HOMBRE | C36: 68309.03 | D36: ASALARIADO | E36: SECTOR PRIVADO | F36: SI | G36: NO | H36: NO | I36: 43
A37: 36 | B37: HOMBRE | D37: ASALARIADO | E37: SECTOR PUBLICO | F37: SI | G37: NO | H37: NO | I37: 62
A38: 37 | B38: HOMBRE | C38: 1552307.5 | D38: ASALARIADO | E38: SECTOR PRIVADO | F38: SI | G38: SI | H38: NO | I38: 41
A39: 38 | B39: HOMBRE | C39: 1531575 | D39: ASEGURADO VOLUNTARIO | E39: SECTOR PRIVADO | F39: SI | G39: SI | H39: NO | I39: 66
A40: 39 | B40: HOMBRE | C40: 3220569.1 | D40: ASALARIADO | E40: SECTOR PRIVADO | F40: SI | G40: NO | H40: NO | I40: 48
A41: 40 | B41: HOMBRE | C41: 658917 | D41: ASALARIADO | E41: SECTOR PUBLICO | F41: SI | G41: NO | H41: SI | I41: 56
A42: 41 | B42: HOMBRE | C42: 631707.6 | D42: ASALARIADO | E42: SECTOR PRIVADO | F42: SI | G42: NO | H42: NO | I42: 25
A43: 42 | B43: MUJER | C43: 977376 | D43: ASALARIADO | E43: SECTOR PRIVADO | F43: SI | G43: NO | H43: NO | I43: 33
A44: 43 | B44: MUJER | C44: 278030 | D44: CONVENIOS ESPECIALES DE TRABAJADORES INDEPENDIENTES | E44: SECTOR PRIVADO | F44: SI | G44: SI | H44: NO | I44: 23
A45: 44 | B45: HOMBRE | C45: 633750 | D45: ASALARIADO | E45: SECTOR PRIVADO | F45: SI | G45: NO | H45: NO | I45: 43
A46: 45 | B46: MUJER | C46: 376776 | D46: ASALARIADO | E46: SECTOR PRIVADO | F46: SI | G46: NO | H46: NO | I46: 27
A47: 46 | B47: MUJER | C47: 1878386.2 | D47: ASALARIADO | E47: SECTOR PRIVADO | F47: SI | G47: NO | H47: NO | I47: 28
...

Sheet Ejercicio 1
A1: Captura de pantalla uso de Power Query:

Sheet Ejercicio 2
A1: Realice un resumen de 5 números incluyendo el promedio. Para las columnas numéricas
A2: Para proceder con el inciso, se toma en cuenta que el resumen de 5 numeros incluyendo el promedio, toma el minimo, el primer cuartil, el segundo cuartil (mediana), el tercer cuartil y el maximo. Además con lo solicitado el promedio. Con ello claro, note que las columnas numericas son: salario y edad.
B3: Salario: | C3: Edad:
A4: Minimo: | B4: =MIN(moras!C2:C5001) -> 10 | C4: =MIN(moras!I2:I5001) -> 14
A5: Primer cuartil: | B5: =_xlfn.QUARTILE.INC(moras!C2:C5001,1) -> 297429 | C5: =_xlfn.QUARTILE.INC(moras!I2:I5001,1) -> 31
A6: Segundo cuartil (Mediana): | B6: =_xlfn.QUARTILE.INC(moras!C2:C5001,2) -> 408495 | C6: =_xlfn.QUARTILE.INC(moras!I2:I5001,2) -> 40
A7: Tercer cuartil: | B7: =_xlfn.QUARTILE.INC(moras!C2:C5001,3) -> 700000 | C7: =_xlfn.QUARTILE.INC(moras!I2:I5001,3) -> 52
A8: Maximo: | B8: =MAX(moras!C2:C5001) -> 16858742 | C8: =MAX(moras!I2:I5001) -> 99
A9: Promedio: | B9: =AVERAGE(moras!C2:C5001) -> 657534.29 | C9: =AVERAGE(moras!I2:I5001) -> 41.906344

Sheet Ejercicio 3
A1: Realice una columna donde se identifiquen valores atípicos haciendo uso del Z-Score, de tal manera que si el valor absoluto del Z-Score es mayor a 1,96 se considera un valor atípico. Esto para la columna de salario y edad.
A2: Para proceder con este ejercicio se conoce que hacer el uzo del Z-Score es aplicar una transformacion lineal a la distribucion de la variable medida, tal que se toma el valor de la fila seleccionada se le resta el promedio de toda la columna y esto se divide por la desviacion estandar de toda la columna, en este caso se considera que el valor absoluta del Z-Score es mayor a 1,96 se considera un valor atipico. Con todo esto claro procedemos:
B3: Salarios | D3: Edad:
B4: Z- Score: | C4: Tipo de valor: | D4: Z-Score: | E4: Tipo de valor:
B5: =(moras!C2 - AVERAGE(moras!$C$2:$C$5001)) / _xlfn.STDEV.P(moras!$C$2:$C$5001) -> -0.8108485 | C5: =IF(ABS(B5)>1.96,"Atipico","Normal") -> Normal | D5: =(moras!I2 - AVERAGE(moras!$I$2:$I$5001)) / _xlfn.STDEV.P(moras!$I$2:$I$5001) -> 0.0066104783 | E5: =IF(ABS(D5)>1.96,"Atipico","Normal") -> Normal
B6: =(moras!C3 - AVERAGE(moras!$C$2:$C$5001)) / _xlfn.STDEV.P(moras!$C$2:$C$5001) -> 3.2771119 | C6: =IF(ABS(B6)>1.96,"Atipico","Normal") -> Atipico | D6: =(moras!I3 - AVERAGE(moras!$I$2:$I$5001)) / _xlfn.STDEV.P(moras!$I$2:$I$5001) -> 2.4769942 | E6: =IF(ABS(D6)>1.96,"Atipico","Normal") -> Atipico
B7: =(moras!C4 - AVERAGE(moras!$C$2:$C$5001)) / _xlfn.STDEV.P(moras!$C$2:$C$5001) -> -0.47729453 | C7: =IF(ABS(B7)>1.96,"Atipico","Normal") -> Normal | D7: =(moras!I4 - AVERAGE(moras!$I$2:$I$5001)) / _xlfn.STDEV.P(moras!$I$2:$I$5001) -> 0.21835766 | E7: =IF(ABS(D7)>1.96,"Atipico","Normal") -> Normal
B8: =(moras!C5 - AVERAGE(moras!$C$2:$C$5001)) / _xlfn.STDEV.P(moras!$C$2:$C$5001) -> -0.13883526 | C8: =IF(ABS(B8)>1.96,"Atipico","Normal") -> Normal | D8: =(moras!I5 - AVERAGE(moras!$I$2:$I$5001)) / _xlfn.STDEV.P(moras!$I$2:$I$5001) -> 0.50068723 | E8: =IF(ABS(D8)>1.96,"Atipico","Normal") -> Normal
B9: =(moras!C6 - AVERAGE(moras!$C$2:$C$5001)) / _xlfn.STDEV.P(moras!$C$2:$C$5001) -> -0.55188378 | C9: =IF(ABS(B9)>1.96,"Atipico","Normal") -> Normal | D9: =(moras!I6 - AVERAGE(moras!$I$2:$I$5001)) / _xlfn.STDEV.P(moras!$I$2:$I$5001) -> 0.0066104783 | E9: =IF(ABS(D9)>1.96,"Atipico","Normal") -> Normal
B10: =(moras!C7 - AVERAGE(moras!$C$2:$C$5001)) / _xlfn.STDEV.P(moras!$C$2:$C$5001) -> -0.32109689 | C10: =IF(ABS(B10)>1.96,"Atipico","Normal") -> Normal | D10: =(moras!I7 - AVERAGE(moras!$I$2:$I$5001)) / _xlfn.STDEV.P(moras!$I$2:$I$5001) -> 0.14777526 | E10: =IF(ABS(D10)>1.96,"Atipico","Normal") -> Normal
B11: =(moras!C8 - AVERAGE(moras!$C$2:$C$5001)) / _xlfn.STDEV.P(moras!$C$2:$C$5001) -> 0.24315272 | C11: =IF(ABS(B11)>1.96,"Atipico","Normal") -> Normal | D11: =(moras!I8 - AVERAGE(moras!$I$2:$I$5001)) / _xlfn.STDEV.P(moras!$I$2:$I$5001) -> -0.27571909 | E11: =IF(ABS(D11)>1.96,"Atipico","Normal") -> Normal
B12: =(moras!C9 - AVERAGE(moras!$C$2:$C$5001)) / _xlfn.STDEV.P(moras!$C$2:$C$5001) -> -0.3163492 | C12: =IF(ABS(B12)>1.96,"Atipico","Normal") -> Normal | D12: =(moras!I9 - AVERAGE(moras!$I$2:$I$5001)) / _xlfn.STDEV.P(moras!$I$2:$I$5001) -> -0.41688388 | E12: =IF(ABS(D12)>1.96,"Atipico","Normal") -> Normal
B13: =(moras!C10 - AVERAGE(moras!$C$2:$C$5001)) / _xlfn.STDEV.P(moras!$C$2:$C$5001) -> -0.48442475 | C13: =IF(ABS(B13)>1.96,"Atipico","Normal") -> Normal | D13: =(moras!I10 - AVERAGE(moras!$I$2:$I$5001)) / _xlfn.STDEV.P(moras!$I$2:$I$5001) -> -1.4756198 | E13: =IF(ABS(D13)>1.96,"Atipico","Normal") -> Normal
B14: =(moras!C11 - AVERAGE(moras!$C$2:$C$5001)) / _xlfn.STDEV.P(moras!$C$2:$C$5001) -> 4.9568222 | C14: =IF(ABS(B14)>1.96,"Atipico","Normal") -> Atipico | D14: =(moras!I11 - AVERAGE(moras!$I$2:$I$5001)) / _xlfn.STDEV.P(moras!$I$2:$I$5001) -> -0.13455431 | E14: =IF(ABS(D14)>1.96,"Atipico","Normal") -> Normal
B15: =(moras!C12 - AVERAGE(moras!$C$2:$C$5001)) / _xlfn.STDEV.P(moras!$C$2:$C$5001) -> 0.66894991 | C15: =IF(ABS(B15)>1.96,"Atipico","Normal") -> Normal | D15: =(moras!I12 - AVERAGE(moras!$I$2:$I$5001)) / _xlfn.STDEV.P(moras!$I$2:$I$5001) -> -0.84037824 | E15: =IF(ABS(D15)>1.96,"Atipico","Normal") -> Normal
B16: =(moras!C13 - AVERAGE(moras!$C$2:$C$5001)) / _xlfn.STDEV.P(moras!$C$2:$C$5001) -> 0.45947458 | C16: =IF(ABS(B16)>1.96,"Atipico","Normal") -> Normal | D16: =(moras!I13 - AVERAGE(moras!$I$2:$I$5001)) / _xlfn.STDEV.P(moras!$I$2:$I$5001) -> 1.1359288 | E16: =IF(ABS(D16)>1.96,"Atipico","Normal") -> Normal
... B5004: =(moras!C5001 - AVERAGE(moras!$C$2:$C$5001)) / _xlfn.STDEV.P(moras!$C$2:$C$5001) -> -0.20773405 | C5004: =IF(ABS(B5004)>1.96,"Atipico","Normal") -> Normal | D5004: =(moras!I5001 - AVERAGE(moras!$I$2:$I$5001)) / _xlfn.STDEV.P(moras!$I$2:$I$5001) -> -0.063971915 | E5004: =IF(ABS(D5004)>1.96,"Atipico","Normal") -> Normal

Sheet Ejercicio 4
A1: Detecte el porcentaje de valores faltantes en cada una de las columnas.
A2: Para proceder con el inciso se utilizo la funcion Contar.Blanco, que según el soporte de Microsoft "se utiliza para contar el numero de celdas vacias en un rango dado". Extaido de https://support.microsoft.com/es-es/office/función-contar-blanco-6a92d772-675c-4bee-b346-24af6bd3ac22 | B2: Porcentajes de NAs:
B3: Identificacion: | C3: =(COUNTBLANK(moras!A2:A5001)) / 5000 * 100 -> 0
B4: Sexo: | C4: =(COUNTBLANK(moras!B2:B5001)) / 5000 * 100 -> 0
B5: Salario: | C5: =(COUNTBLANK(moras!C2:C5001) / 5000) * 100 -> 0.06
B6: Tipo_Aseguramiento: | C6: =(COUNTBLANK(moras!D2:D5001) / 5000 )* 100 -> 0.04
B7: Sector: | C7: =(COUNTBLANK(moras!E2:E5001)) / 5000 * 100 -> 0
B8: Indicador_Activo: | C8: =COUNTBLANK(moras!F2:F5001) / 5000 * 100 -> 0
B9: Indicador.Extranjero | C9: =(COUNTBLANK(moras!G2:G5001)) / 5000 * 100 -> 0
B10: Indicador.Moroso | C10: =COUNTBLANK(moras!H2:H5001) / 5000 * 100 -> 0
B11: Edad: | C11: =(COUNTBLANK(moras!I2:I5001)) / 5000 * 100 -> 0.06

Sheet Ejercicio 5
A1: Impute los valores faltantes haciendo uso de algún método de su preferencia.
A2: Para la imputación de los salarios y edades, al ser variables numericas procedemos a sustituir las celdas vacias por el promedio. En el caso de los Tipos_Aseguramientos como es una variable categorica procedemos por la moda tal que:
A3: Ahora bien para calcular la moda, se procede mediante las funciones INDICE, COINCIDIR, CONTAR.SI y MAX. Que deacuerdo a el soporte de microsoft la funcion indice devuelve el valor de una celda especifica o de una matriz de celdas y la funcion coincidir busca un elemento determinado en un intervalo de celdas y luego devuelve la posición relativ de dicho elemento en el rango. Extraido de: https://support.microsoft.com/es-es/office/función-coincidir-e8dffd45-c762-47d6-bf89-533f4a37673a y de https://support.microsoft.com/es-es/office/indice-función-indice-a5dcf0dd-996d-40a4-a822-b56b061328bd. Entonces la funcion determinada para la moda, cuenta cuantas veces aparece cada categoria, busca su maximo (cual se repite más) y usando esa posición devuelve el valor que corresponde, identificando así la categoría mas frecuente.
A4: Moda de Tipos_Aseguramientos: | B4: {=INDEX(moras!D2:D5001, MATCH(MAX(COUNTIF(moras!D2:D5001, moras!D2:D5001)), COUNTIF(moras!D2:D5001, moras!D2:D5001), 0))} -> ASALARIADO
A7: Promedios extraidos de ejercicio 2.
A8: Promedio de Salarios: | B8: =AVERAGE(moras!C2:C5001) -> 657534.29
A9: Promedio de Edades: | B9: =ROUND(AVERAGE(moras!I2:I5001),0) -> 42
A12: Ahora utilizamos la funcion esblanco para sustituir los Nas con los datos calculados, pues según el soporte de microsoft la funcion esblanco "devuelve el valor lógico VERDADERO si el argumento de valor es una referencia a una celda vacía, de lo contrario, devuelve FALSO"- Extraido de: https://support.microsoft.com/es-es/office/funciones-es-0f2d7971-6019-40a0-a171-f2d869135665
B13: Tabla con Nas imputados
B14: IDENTIFICACION | C14: SEXO | D14: SALARIO | E14: TIPO_ASEGURAMIENTO | F14: SECTOR | G14: INDICADOR_ACTIVO | H14: INDICADOR.EXTRANJERO | I14: INDICADOR_MOROSO | J14: EDAD | K14: SALARIOS IMPUTADOS | L14: TIPO_ASEGURADOS_IMPUTADOS | M14: EDAD IMPUTADA
B15: 1 | C15: HOMBRE | E15: ASALARIADO | F15: SECTOR PUBLICO | G15: SI | H15: NO | I15: NO | J15: 42 | K15: =IF(ISBLANK(D15),$B$8,D15) -> 657534.29 | L15: =IF(ISBLANK(E15),$B$4,E15) -> ASALARIADO | M15: =IF(ISBLANK(J15),$B$9,J15) -> 42
B16: 2 | C16: HOMBRE | D16: 3315014 | E16: PENSIONADOS EN SU PROPIO SISTEMA | F16: SECTOR PUBLICO | G16: SI | H16: NO | I16: NO | J16: 77 | K16: =IF(ISBLANK(D16),$B$8,D16) -> 3315014 | L16: =IF(ISBLANK(E16),$B$4,E16) -> PENSIONADOS EN SU PROPIO SISTEMA | M16: =IF(ISBLANK(J16),$B$9,J16) -> 77
B17: 3 | C17: MUJER | D17: 270486.01 | E17: ASALARIADO | F17: SECTOR PRIVADO | G17: SI | H17: NO | I17: NO | J17: 45 | K17: =IF(ISBLANK(D17),$B$8,D17) -> 270486.01 | L17: =IF(ISBLANK(E17),$B$4,E17) -> ASALARIADO | M17: =IF(ISBLANK(J17),$B$9,J17) -> 45
B18: 4 | C18: MUJER | D18: 544949.83 | E18: ASALARIADO | F18: SECTOR PRIVADO | G18: SI | H18: NO | I18: NO | J18: 49 | K18: =IF(ISBLANK(D18),$B$8,D18) -> 544949.83 | L18: =IF(ISBLANK(E18),$B$4,E18) -> ASALARIADO | M18: =IF(ISBLANK(J18),$B$9,J18) -> 49
B19: 5 | C19: MUJER | D19: 210000 | E19: ASALARIADO | F19: SECTOR PRIVADO | G19: SI | H19: NO | I19: NO | J19: 42 | K19: =IF(ISBLANK(D19),$B$8,D19) -> 210000 | L19: =IF(ISBLANK(E19),$B$4,E19) -> ASALARIADO | M19: =IF(ISBLANK(J19),$B$9,J19) -> 42
B20: 6 | C20: HOMBRE | D20: 397150 | E20: ASALARIADO | F20: SECTOR PRIVADO | G20: SI | H20: NO | I20: NO | J20: 44 | K20: =IF(ISBLANK(D20),$B$8,D20) -> 397150 | L20: =IF(ISBLANK(E20),$B$4,E20) -> ASALARIADO | M20: =IF(ISBLANK(J20),$B$9,J20) -> 44
B21: 7 | C21: HOMBRE | D21: 854712 | E21: ASALARIADO | F21: SECTOR PRIVADO | G21: SI | H21: NO | I21: NO | J21: 38 | K21: =IF(ISBLANK(D21),$B$8,D21) -> 854712 | L21: =IF(ISBLANK(E21),$B$4,E21) -> ASALARIADO | M21: =IF(ISBLANK(J21),$B$9,J21) -> 38
B22: 8 | C22: HOMBRE | D22: 401000 | E22: ASALARIADO | F22: SECTOR PRIVADO | G22: SI | H22: SI | I22: SI | J22: 36 | K22: =IF(ISBLANK(D22),$B$8,D22) -> 401000 | L22: =IF(ISBLANK(E22),$B$4,E22) -> ASALARIADO | M22: =IF(ISBLANK(J22),$B$9,J22) -> 36
B23: 9 | C23: MUJER | D23: 264703.96 | E23: ASALARIADO | F23: SECTOR PRIVADO | G23: SI | H23: NO | I23: NO | J23: 21 | K23: =IF(ISBLANK(D23),$B$8,D23) -> 264703.96 | L23: =IF(ISBLANK(E23),$B$4,E23) -> ASALARIADO | M23: =IF(ISBLANK(J23),$B$9,J23) -> 21
B24: 10 | C24: HOMBRE | D24: 4677126.8 | E24: ASALARIADO | F24: SECTOR PRIVADO | G24: SI | H24: NO | I24: NO | J24: 40 | K24: =IF(ISBLANK(D24),$B$8,D24) -> 4677126.8 | L24: =IF(ISBLANK(E24),$B$4,E24) -> ASALARIADO | M24: =IF(ISBLANK(J24),$B$9,J24) -> 40
B25: 11 | C25: MUJER | D25: 1200000 | E25: ASALARIADO | F25: SECTOR PRIVADO | G25: SI | H25: NO | I25: NO | J25: 30 | K25: =IF(ISBLANK(D25),$B$8,D25) -> 1200000 | L25: =IF(ISBLANK(E25),$B$4,E25) -> ASALARIADO | M25: =IF(ISBLANK(J25),$B$9,J25) -> 30
B26: 12 | C26: MUJER | D26: 1030132 | E26: ASALARIADO | F26: SECTOR PUBLICO | G26: SI | H26: NO | I26: SI | J26: 58 | K26: =IF(ISBLANK(D26),$B$8,D26) -> 1030132 | L26: =IF(ISBLANK(E26),$B$4,E26) -> ASALARIADO | M26: =IF(ISBLANK(J26),$B$9,J26) -> 58
B27: 13 | C27: HOMBRE | D27: 731287.5 | E27: ASALARIADO | F27: SECTOR PUBLICO | G27: SI | H27: NO | I27: NO | J27: 40 | K27: =IF(ISBLANK(D27),$B$8,D27) -> 731287.5 | L27: =IF(ISBLANK(E27),$B$4,E27) -> ASALARIADO | M27: =IF(ISBLANK(J27),$B$9,J27) -> 40
... B34: 20 | C34: MUJER | D34: 309820 | E34: ASEGURADO VOLUNTARIO | F34: SECTOR PRIVADO | G34: SI | H34: SI | I34: SI | J34: 52 | K34: =IF(ISBLANK(D34),$B$8,D34) -> 309820 | L34: =IF(ISBLANK(E34),$B$4,E34) -> ASEGURADO VOLUNTARIO | M34: =IF(ISBLANK(J34),$B$9,J34) -> 52
B35: 21 | C35: MUJER | E35: ASALARIADO | F35: SECTOR PRIVADO | G35: SI | H35: SI | I35: NO | J35: 28 | K35: =IF(ISBLANK(D35),$B$8,D35) -> 657534.29 | L35: =IF(ISBLANK(E35),$B$4,E35) -> ASALARIADO | M35: =IF(ISBLANK(J35),$B$9,J35) -> 28
B36: 22 | C36: HOMBRE | D36: 278030 | E36: CONVENIOS ESPECIALES DE TRABAJADORES INDEPENDIENTES | F36: SECTOR PRIVADO | G36: SI | H36: NO | I36: NO | J36: 59 | K36: =IF(ISBLANK(D36),$B$8,D36) -> 278030 | L36: =IF(ISBLANK(E36),$B$4,E36) -> CONVENIOS ESPECIALES DE TRABAJADORES INDEPENDIENTES | M36: =IF(ISBLANK(J36),$B$9,J36) -> 59
B37: 23 | C37: HOMBRE | D37: 2124814 | E37: ASALARIADO | F37: SECTOR PRIVADO | G37: SI | H37: NO | I37: NO | J37: 32 | K37: =IF(ISBLANK(D37),$B$8,D37) -> 2124814 | L37: =IF(ISBLANK(E37),$B$4,E37) -> ASALARIADO | M37: =IF(ISBLANK(J37),$B$9,J37) -> 32
B38: 24 | C38: HOMBRE | D38: 191744.68 | E38: ASALARIADO | F38: SECTOR PRIVADO | G38: SI | H38: NO | I38: NO | J38: 18 | K38: =IF(ISBLANK(D38),$B$8,D38) -> 191744.68 | L38: =IF(ISBLANK(E38),$B$4,E38) -> ASALARIADO | M38: =IF(ISBLANK(J38),$B$9,J38) -> 18
B39: 25 | C39: MUJER | D39: 1117489 | E39: ASALARIADO | F39: SECTOR PUBLICO | G39: SI | H39: NO | I39: SI | J39: 36 | K39: =IF(ISBLANK(D39),$B$8,D39) -> 1117489 | L39: =IF(ISBLANK(E39),$B$4,E39) -> ASALARIADO | M39: =IF(ISBLANK(J39),$B$9,J39) -> 36
B40: 26 | C40: HOMBRE | D40: 1451530 | E40: PENSIONADOS EN SU PROPIO SISTEMA | F40: SECTOR PUBLICO | G40: SI | H40: NO | I40: NO | J40: 62 | K40: =IF(ISBLANK(D40),$B$8,D40) -> 1451530 | L40: =IF(ISBLANK(E40),$B$4,E40) -> PENSIONADOS EN SU PROPIO SISTEMA | M40: =IF(ISBLANK(J40),$B$9,J40) -> 62
B41: 27 | C41: HOMBRE | D41: 66700 | E41: ASALARIADO | F41: SECTOR PRIVADO | G41: SI | H41: NO | I41: NO | J41: 38 | K41: =IF(ISBLANK(D41),$B$8,D41) -> 66700 | L41: =IF(ISBLANK(E41),$B$4,E41) -> ASALARIADO | M41: =IF(ISBLANK(J41),$B$9,J41) -> 38
B42: 28 | C42: MUJER | D42: 73410 | E42: ASALARIADO | F42: SECTOR PRIVADO | G42: SI | H42: SI | I42: NO | J42: 22 | K42: =IF(ISBLANK(D42),$B$8,D42) -> 73410 | L42: =IF(ISBLANK(E42),$B$4,E42) -> ASALARIADO | M42: =IF(ISBLANK(J42),$B$9,J42) -> 22
B43: 29 | C43: HOMBRE | D43: 815355.66 | E43: ASALARIADO | F43: SECTOR PUBLICO | G43: SI | H43: NO | I43: NO | J43: 42 | K43: =IF(ISBLANK(D43),$B$8,D43) -> 815355.66 | L43: =IF(ISBLANK(E43),$B$4,E43) -> ASALARIADO | M43: =IF(ISBLANK(J43),$B$9,J43) -> 42
B44: 30 | C44: HOMBRE | D44: 398125 | E44: ASALARIADO | F44: SECTOR PRIVADO | G44: SI | H44: NO | I44: NO | J44: 38 | K44: =IF(ISBLANK(D44),$B$8,D44) -> 398125 | L44: =IF(ISBLANK(E44),$B$4,E44) -> ASALARIADO | M44: =IF(ISBLANK(J44),$B$9,J44) -> 38
B45: 31 | C45: HOMBRE | D45: 606763.96 | E45: ASALARIADO | F45: SECTOR PRIVADO | G45: SI | H45: NO | I45: NO | J45: 39 | K45: =IF(ISBLANK(D45),$B$8,D45) -> 606763.96 | L45: =IF(ISBLANK(E45),$B$4,E45) -> ASALARIADO | M45: =IF(ISBLANK(J45),$B$9,J45) -> 39
B46: 32 | C46: HOMBRE | D46: 360420 | E46: TRABAJADOR INDEPENDIENTE | F46: SECTOR PRIVADO | G46: SI | H46: NO | I46: SI | J46: 53 | K46: =IF(ISBLANK(D46),$B$8,D46) -> 360420 | L46: =IF(ISBLANK(E46),$B$4,E46) -> TRABAJADOR INDEPENDIENTE | M46: =IF(ISBLANK(J46),$B$9,J46) -> 53
B47: 33 | C47: MUJER | D47: 297046 | E47: ASALARIADO | F47: SECTOR PRIVADO | G47: SI | H47: SI | I47: NO | J47: 41 | K47: =IF(ISBLANK(D47),$B$8,D47) -> 297046 | L47: =IF(ISBLANK(E47),$B$4,E47) -> ASALARIADO | M47: =IF(ISBLANK(J47),$B$9,J47) -> 41
... B49: 35 | C49: HOMBRE | D49: 68309.03 | E49: ASALARIADO | F49: SECTOR PRIVADO | G49: SI | H49: NO | I49: NO | J49: 43 | K49: =IF(ISBLANK(D49),$B$8,D49) -> 68309.03 | L49: =IF(ISBLANK(E49),$B$4,E49) -> ASALARIADO | M49: =IF(ISBLANK(J49),$B$9,J49) -> 43
B50: 36 | C50: HOMBRE | E50: ASALARIADO | F50: SECTOR PUBLICO | G50: SI | H50: NO | I50: NO | J50: 62 | K50: =IF(ISBLANK(D50),$B$8,D50) -> 657534.29 | L50: =IF(ISBLANK(E50),$B$4,E50) -> ASALARIADO | M50: =IF(ISBLANK(J50),$B$9,J50) -> 62
B51: 37 | C51: HOMBRE | D51: 1552307.5 | E51: ASALARIADO | F51: SECTOR PRIVADO | G51: SI | H51: SI | I51: NO | J51: 41 | K51: =IF(ISBLANK(D51),$B$8,D51) -> 1552307.5 | L51: =IF(ISBLANK(E51),$B$4,E51) -> ASALARIADO | M51: =IF(ISBLANK(J51),$B$9,J51) -> 41
...

Sheet Ejercicio 6
A1: Realice gráficos donde se vea la cantidad de individuos por cada categoría. Analice los resultados.
A2: Para ello realicemos una tabla adecuada para los graficos solicitados:
B3: Tablas necesarias para graficar
B4: Sexo | C4: Conteo | E4: Sector: | F4: Conteo | H4: Tipo_Asegurado: | I4: Conteo | K4: Indicador_Activo | L4: Conteo | N4: Indicador.Extranjero | O4: Conteo | Q4: Indicador.Moroso | R4: Conteo
B5: Hombres: | C5: =COUNTIF(moras!$B$2:$B$5001, "HOMBRE") -> 3012 | E5: Sector Publico: | F5: =COUNTIF(moras!$E$2:$E$5001, "SECTOR PUBLICO") -> 1094 | H5: Asalariados: | I5: =COUNTIF(moras!$D$2:$D$5001, "ASALARIADO") -> 3462 | K5: Si: | L5: =COUNTIF(moras!$F$2:$F$5001, "SI") -> 4966 | N5: Si: | O5: =COUNTIF(moras!$G$2:$G$5001, "SI") -> 603 | Q5: Si: | R5: =COUNTIF(moras!$H$2:$H$5001, "SI") -> 870
B6: Mujeres: | C6: =COUNTIF(moras!$B$2:$B$5001, "MUJER") -> 1988 | E6: Sector Privado: | F6: =COUNTIF(moras!$E$2:$E$5002, "SECTOR PRIVADO") -> 3906 | H6: Asegurado voluntario: | I6: =COUNTIF(moras!$D$2:$D$5001, "ASEGURADO VOLUNTARIO") -> 436 | K6: No: | L6: =COUNTIF(moras!$F$2:$F$5001, "NO") -> 34 | N6: No: | O6: =COUNTIF(moras!$G$2:$G$5001, "NO") -> 4397 | Q6: No: | R6: =COUNTIF(moras!$H$2:$H$5001, "NO") -> 4130
H7: Convenios Especiales de asegurados voluntarios: | I7: =COUNTIF(moras!$D$2:$D$5001, "CONVENIOS ESPECIALES DE ASEGURADOS VOLUNTARIOS") -> 31
H8: Convenios Especiales de trabajadores independientes: | I8: =COUNTIF(moras!$D$2:$D$5001, "CONVENIOS ESPECIALES DE TRABAJADORES INDEPENDIENTES") -> 157
H9: Pensionadosen su propio sistema: | I9: =COUNTIF(moras!$D$2:$D$5001, "PENSIONADOS EN SU PROPIO SISTEMA") -> 212
H10: Trabajador independiente | I10: =COUNTIF(moras!$D$1:$D$5001, "TRABAJADOR INDEPENDIENTE") -> 700
B25: Analsis de resultados: | H25: Analsis de resultados: | K25: Analsis de resultados:
B26: Notese que al tener una mayor poblacion masculina participando en los asegurados tendremos tendencias mayormente marcadas por el compartamiento masculino. | H26: La mayoría de las personas pertenecen al grupo de Asalariados, representando con diferencia el mayor volumen del conjunto. En contraste, categorías como Convenios Especiales y Pensionados en su propio sistema tienen una participación muy baja. Tendremos un dominio notorio por los asalariados. | K26: Al tomar una gran parte del conjunto con indicadores no extranjeros se puede asumir que se toma una vision en mayor parte nacional de los asegurados y sus caracteristicas principales.
B40: Analsis de resultados: | H40: Analsis de resultados: | K40: Analsis de resultados:
B41: Tenemos un apropiamiento de gran parte del conjunto de datos por parte del sector privado lo que destinara un mayor interes en el comportamiento del sector privado. | H41: Tenemos una alta superioridad de los indicadores activos por lo que se asegura una analsis pertienente con respecto a la vision de personas con seguros adquiridos. | K41: Se denota un cumplimiento general del pago de los asegurados, pues el porcentaje de morasidad es relativamente bajo en comparacion con los no morosos, dando confianza al lanzamiento de seguros mas dependientes al pago del asegurado.

Sheet Ejercicio 7
A1: Realice un gráfico para cada una de las variables categóricas en donde se vea el porcentaje de personas morosa por cada clase. Analice los resultados.
B3: Variable categorica: | C3: Morosidad %:
B4: Hombres: | C4: =(COUNTIFS(moras!$B$2:$B$5001, "HOMBRE",moras!$H$2:$H$5001, "Si")/'Ejercicio 6'!C5)*100 -> 17.729084
B5: Mujeres: | C5: =(COUNTIFS(moras!$B$2:$B$5001, "MUJER",moras!$H$2:$H$5001, "Si")/'Ejercicio 6'!C6)*100 -> 16.901408
B6: Sector Publico: | C6: =(COUNTIFS(moras!$E$2:$E$5001, "SECTOR PUBLICO",moras!$H$2:$H$5001, "Si")/'Ejercicio 6'!F5)*100 -> 15.173675
B7: Sector Privado: | C7: =(COUNTIFS(moras!$E$2:$E$5001, "SECTOR PRIVADO",moras!$H$2:$H$5001, "Si")/'Ejercicio 6'!F6)*100 -> 18.023554
B8: Asalariados: | C8: =(COUNTIFS(moras!$D$2:$D$5001, "ASALARIADO",moras!$H$2:$H$5001, "Si")/'Ejercicio 6'!I5)*100 -> 11.958406
B9: Asegurado voluntario: | C9: =(COUNTIFS(moras!$D$2:$D$5001, "ASEGURADO VOLUNTARIO",moras!$H$2:$H$5001, "Si")/'Ejercicio 6'!I6)*100 -> 13.302752
B10: Convenios Especiales de asegurados voluntarios: | C10: =(COUNTIFS(moras!$D$2:$D$5001, "CONVENIOS ESPECIALES DE ASEGURADOS VOLUNTARIOS",moras!$H$2:$H$5001, "Si")/'Ejercicio 6'!I7)*100 -> 0
B11: Convenios Especiales de trabajadores independientes: | C11: =(COUNTIFS(moras!$D$2:$D$5001, "CONVENIOS ESPECIALES DE TRABAJADORES INDEPENDIENTES",moras!$H$2:$H$5001, "Si")/'Ejercicio 6'!I8)*100 -> 2.5477707
B12: Pensionados en su propio sistema: | C12: =(COUNTIFS(moras!$D$2:$D$5001, "PENSIONADOS EN SU PROPIO SISTEMA",moras!$H$2:$H$5001, "Si")/'Ejercicio 6'!I9)*100 -> 0
B13: Trabajador independiente: | C13: =(COUNTIFS(moras!$D$2:$D$5001, "TRABAJADOR INDEPENDIENTE",moras!$H$2:$H$5001, "Si")/'Ejercicio 6'!I10)*100 -> 56.142857
B14: Indicador inactivo | C14: =(COUNTIFS(moras!$F$2:$F$5001, "NO",moras!$H$2:$H$5001, "Si")/'Ejercicio 6'!L6)*100 -> 52.941176
B15: Indicador activo | C15: =(COUNTIFS(moras!$F$2:$F$5001, "SI",moras!$H$2:$H$5001, "Si")/'Ejercicio 6'!L5)*100 -> 17.156665
B16: Extranjero | C16: =(COUNTIFS(moras!$G$2:$G$5001, "SI",moras!$H$2:$H$5001, "Si")/'Ejercicio 6'!O5)*100 -> 24.046434
B17: No extranjero | C17: =(COUNTIFS(moras!$G$2:$G$5001, "NO",moras!$H$2:$H$5001, "Si")/'Ejercicio 6'!O6)*100 -> 16.488515
E19: Analisis de resultados:
E20: Con respecto al analisis de resultados se denota que, los niveles de morosidad se encuentran relativamente altos en los trabajadores independientes y aquellas personas que no tengan un seguro activo, es claro que se encuentran en morosidad los que no poseen un seguro activo pues esto puede presentarse por la falta de pago acumulada y al cancelacion posterior a ello. Por otra parte, es preocupante como los trabajadores independientes descuidan el pago de sus cuotas. Además note que poseemos algunas variables con una morosidad igual a cero, para los pensionados en su propio sistema es entendible que no sean morosos pues mantienen un sistema privado de asegurarse, en especial es curioso observar como los convenios especiales de asegurados voluntarios no son del todo morosos, ello se puede presentar por politicas adecuadas de organizacion con pagos de seguros vinculados y una cantidad relativamente baja de seguros abarcados.Por último, se denota que la morosidad ocila entre los valores de un 13% a un 24% en las demas variables categoricas, ello puede darse por las condiciones economicas diversas de cada uno de los sectores analisados y por crisis inesperadas.

Sheet Ejercicio 8
A1: Para las variables numéricas realice gráficos de barras donde se ponga un color de acuerdo a si es moroso o no. Analice los resultados.
B3: Variables numericas con morosidad:
B4: Rango edad: | C4: Cantidad Morosos: | D4: Cantidad no Morosos:
B5: 0-25 | C5: =COUNTIFS(moras!$I$2:$I$5001, ">=0", moras!$I$2:$I$5001, "<=25", moras!$H$2:$H$5001, "SI") -> 51 | D5: =COUNTIFS(moras!$I$2:$I$5001, ">=0", moras!$I$2:$I$5001, "<=25", moras!$H$2:$H$5001, "NO") -> 500
B6: 26-35 | C6: =COUNTIFS(moras!$I$2:$I$5001, ">=26", moras!$I$2:$I$5001, "<=35", moras!$H$2:$H$5001, "SI") -> 191 | D6: =COUNTIFS(moras!$I$2:$I$5001, ">=26", moras!$I$2:$I$5001, "<=35", moras!$H$2:$H$5001, "NO") -> 1163
B7: 36-45 | C7: =COUNTIFS(moras!$I$2:$I$5001, ">=36", moras!$I$2:$I$5001, "<=45", moras!$H$2:$H$5001, "SI") -> 254 | D7: =COUNTIFS(moras!$I$2:$I$5001, ">=36", moras!$I$2:$I$5001, "<=45", moras!$H$2:$H$5001, "NO") -> 999
B8: 46-55 | C8: =COUNTIFS(moras!$I$2:$I$5001, ">=46", moras!$I$2:$I$5001, "<=55", moras!$H$2:$H$5001, "SI") -> 212 | D8: =COUNTIFS(moras!$I$2:$I$5001, ">=46", moras!$I$2:$I$5001, "<=55", moras!$H$2:$H$5001, "NO") -> 700
B9: 56-66 | C9: =COUNTIFS(moras!$I$2:$I$5001, ">=56", moras!$I$2:$I$5001, "<=66", moras!$H$2:$H$5001, "SI") -> 131 | D9: =COUNTIFS(moras!$I$2:$I$5001, ">=56", moras!$I$2:$I$5001, "<=66", moras!$H$2:$H$5001, "NO") -> 538
B10: 66+ | C10: =COUNTIFS(moras!$I$2:$I$5001, ">=66", moras!$H$2:$H$5001, "SI") -> 37 | D10: =COUNTIFS(moras!$I$2:$I$5001, ">=66", moras!$H$2:$H$5001, "NO") -> 241
F18: Analisis de resultados:
F19: Los resultados muestran que la morosidad tiende a concentrarse en los grupos de edad 36–55 años, lo cual sugiere que las personas en edades productivas medias enfrentan mayores presiones económicas o compromisos financieros que incrementan el riesgo de caer en morasidad. De alli que la mayor cantidad de morosos se encuentren entre los 26-55 años de edad. Además, los grupos jóvenes (14–25) y mayores (>66) presentan la menor morosidad, posiblemente por menor carga crediticia, subsidios o estabilidad en ingresos (como pensiones).
B23: Variables numericas con morosidad:
B24: Rango de salarios: | C24: Cantidad Morosos: | D24: Cantidad no Morosos:
B25: 0-300000 | C25: =COUNTIFS(moras!$C$2:$C$5001, ">=0", moras!$C$2:$C$5001, "<300000", moras!$H$2:$H$5001, "SI") -> 259 | D25: =COUNTIFS(moras!$C$2:$C$5001, ">=0", moras!$C$2:$C$5001, "<300000", moras!$H$2:$H$5001, "NO") -> 1109
B26: 300001-600000 | C26: =COUNTIFS(moras!$C$2:$C$5001, ">=300001", moras!$C$2:$C$5001, "<600000", moras!$H$2:$H$5001, "SI") -> 423 | D26: =COUNTIFS(moras!$C$2:$C$5001, ">=300001", moras!$C$2:$C$5001, "<600000", moras!$H$2:$H$5001, "NO") -> 1611
B27: 600000+ | C27: =COUNTIFS(moras!$C$2:$C$5001, ">=600001", moras!$H$2:$H$5001, "SI") -> 183 | D27: =COUNTIFS(moras!$C$2:$C$5001, ">=600001", moras!$H$2:$H$5001, "NO") -> 1378
F37: Analisis de resultados:
F38: Con respecto a los resultados se muestra que la morosidad es mayor en el grupo salarial medio (300 001–600 000), donde se concentra la mayor cantidad de personas, mientras que los salarios bajos presentan morosidad moderada y los salarios altos (600 000+) muestran la menor incidencia. En general, la tendencia sugiere que las personas con ingresos medios enfrentan mayor presión o carga financiera, mientras que quienes tienen ingresos altos mantienen un mejor comportamiento de pago. Ello tambien se puede ver influido por los rangos tomados para un posterior analisis puede tomarse rangos mas cortos y mejor divididos.
